<?xml version="1.0"?>
<robot xmlns:xacro="http://www.ros.org/wiki/xacro"  name="robot">

    <!-- FEMUR LINK -->

    <joint name="left_hip-femur_joint" type="revolute">
        <parent link="left_hip"/>
        <child link="left_femur"/>
        <origin xyz="-0.03 -0.00135 -0.0661" rpy="0 0 0"/>
        <axis xyz="0 -1 0"/>
        <limit lower="0" upper="${pi/4}" velocity="100" effort="100"/>
    </joint>

    <link name="left_femur">
        <visual>
            <origin xyz="0 0 0" rpy="${pi/2} 0 0"/>
            <geometry>
                <mesh filename="package://droid/description/meshes/legs/femur.STL" scale="0.001 0.001 0.001"/>
            </geometry>
            <material name="white"/>
        </visual>
    </link>

    <!-- TIBIA LINK -->

    <joint name="left_femur-tibia_joint" type="revolute">
        <parent link="left_femur"/>
        <child link="left_tibia"/>
        <origin xyz="0 0 -0.08" rpy="0 0 0"/>
        <axis xyz="0 1 0"/>
        <limit lower="0" upper="${pi/4}" velocity="100" effort="100"/>
    </joint>

    <link name="left_tibia">
        <visual>
            <origin xyz="0 0 -0.08" rpy="${pi/2} 0 0"/>
            <geometry>
                <mesh filename="package://droid/description/meshes/legs/tibia.STL" scale="0.001 0.001 0.001"/>
            </geometry>
            <material name="white"/>
        </visual>
    </link>

</robot>