<?xml version="1.0"?>
<robot xmlns:xacro="http://www.ros.org/wiki/xacro"  name="robot">

    <!-- FEMUR LINK -->

    <joint name="right_hip-femur_joint" type="revolute">
        <parent link="right_hip"/>
        <child link="right_femur"/>
        <origin xyz="-0.03 0.00135 -0.0661" rpy="0 0 0"/>
        <axis xyz="0 -1 0"/>
        <limit lower="0" upper="${pi/4}" velocity="100" effort="100"/>
    </joint>

    <link name="right_femur">
        <visual>
            <origin xyz="0 0 0" rpy="${pi/2} 0 0"/>
            <geometry>
                <mesh filename="package://droid/description/meshes/legs/femur.STL" scale="0.001 0.001 0.001"/>
            </geometry>
            <material name="blue"/>
        </visual>
        <collision>
            <origin xyz="0 0 0" rpy="${pi/2} 0 0"/>
            <geometry>
                <mesh filename="package://droid/description/meshes/legs/femur.STL" scale="0.001 0.001 0.001"/>
            </geometry>
        </collision>
        <inertial>
            <origin xyz="0.00119 0 -0.03859" rpy="0 0 0"/>
            <mass value="0.04038"/>
            <inertia ixx="0.000024549"  ixy="0"  ixz="0.000000183"
            iyy="0.000018945" iyz="0" izz="0.000007508"/>
        </inertial>
    </link>

    <!-- TIBIA LINK -->

    <joint name="right_femur-tibia_joint" type="revolute">
        <parent link="right_femur"/>
        <child link="right_tibia"/>
        <origin xyz="0 0 -0.08" rpy="0 0 0"/>
        <axis xyz="0 1 0"/>
        <limit lower="0" upper="${pi/2}" velocity="100" effort="100"/>
    </joint>

    <link name="right_tibia">
        <visual>
            <origin xyz="0 0 0" rpy="${pi/2} 0 0"/>
            <geometry>
                <mesh filename="package://droid/description/meshes/legs/tibia.STL" scale="0.001 0.001 0.001"/>
            </geometry>
            <material name="blue"/>
        </visual>
        <collision>
            <origin xyz="0 0 0" rpy="${pi/2} 0 0"/>
            <geometry>
                <mesh filename="package://droid/description/meshes/legs/tibia.STL" scale="0.001 0.001 0.001"/>
            </geometry>
        </collision>
        <inertial>
            <origin xyz="0.00447 0 -0.02276" rpy="0 0 0"/>
            <mass value="0.01338"/>
            <inertia ixx="0.000008839"  ixy="0"  ixz="0.000001782"
            iyy="0.000009491" iyz="0" izz="0.000001336"/>
        </inertial>
    </link>

    <!-- FOOT LINK -->

    <joint name="right_tibia-foot_joint" type="revolute">
        <parent link="right_tibia"/>
        <child link="right_foot"/>
        <origin xyz="0 0 -0.0625" rpy="0 0 0"/>
        <axis xyz="0 1 0"/>
        <limit lower="${-pi/4}" upper="${pi/4}" velocity="100" effort="100"/>
    </joint>

    <link name="right_foot">
        <visual>
            <origin xyz="0.002 0 -0.02174" rpy="${pi/2} 0 ${pi}"/>
            <geometry>
                <mesh filename="package://droid/description/meshes/legs/foot.STL" scale="0.001 0.001 0.001"/>
            </geometry>
            <material name="blue"/>
        </visual>
        <collision>
            <origin xyz="0.002 0 -0.02174" rpy="${pi/2} 0 ${pi}"/>
            <geometry>
                <mesh filename="package://droid/description/meshes/legs/foot.STL" scale="0.001 0.001 0.001"/>
            </geometry>
        </collision>
        <inertial>
            <origin xyz="-0.00689 0 -0.03048" rpy="0 0 0"/>
            <mass value="0.04904"/>
            <inertia ixx="0.000023179"  ixy="0"  ixz="-0.000001838"
            iyy="0.000038895" iyz="0" izz="0.000040501"/>
        </inertial>
    </link>

</robot>