<?xml version="1.0"?>
<robot xmlns:xacro="http://www.ros.org/wiki/xacro">

    <!-- BASE LINK -->

    <link name="base_link"/>

    <!-- CHASSIS LINK -->

    <joint name="chassis_joint" type="fixed">
        <parent link="base_link"/>
        <child link="chassis"/>
        <origin xyz="0 0 0.25" rpy="0 0 0"/>
    </joint>

    <link name="chassis">
        <visual>
            <origin xyz="0.03992 0.11293 -0.02583" rpy="${pi/2} 0 0"/>
            <geometry>
                <mesh filename="package://droid/description/meshes/chassis.STL" scale="0.001 0.001 0.001"/>
            </geometry>
            <material name="white"/>
        </visual>
        <collision>
            <origin xyz="0.03992 0.11293 -0.02583" rpy="${pi/2} 0 0"/>
            <geometry>
                <mesh filename="package://droid/description/meshes/chassis.STL" scale="0.001 0.001 0.001"/>
            </geometry>
        </collision>
        <inertial>
            <origin xyz="-0.00335 0 0.04408" rpy="0 0 0"/>
            <mass value="0.710"/>
            <inertia ixx="0.001020342"  ixy="-0.000029751"  ixz="0.000081459"
            iyy="0.001357339" iyz="-0.000026283" izz="0.001569161"/>
        </inertial>
    </link>

    <!-- LEFT HIP LINK -->

    <joint name="left_hip_joint" type="revolute">
        <parent link="chassis"/>
        <child link="left_hip"/>
        <origin xyz="0 0.0461 0" rpy="0 0 0"/>
        <axis xyz="0 0 1"/>
        <limit lower="0" upper="${pi/6}" velocity="100" effort="100"/>
    </joint>

    <link name="left_hip">
        <visual>
            <origin xyz="-0.05164 0.06573 -0.08226" rpy="${pi/2} 0 0"/>
            <geometry>
                <mesh filename="package://droid/description/meshes/left_hip.STL" scale="0.001 0.001 0.001"/>
            </geometry>
            <material name="orange"/>
        </visual>
        <collision>
            <origin xyz="-0.05164 0.06573 -0.08226" rpy="${pi/2} 0 0"/>
            <geometry>
                <mesh filename="package://droid/description/meshes/left_hip.STL" scale="0.001 0.001 0.001"/>
            </geometry>
        </collision>
        <inertial>
            <origin xyz="-0.001594 -0.00051 -0.04019" rpy="0 0 0"/>
            <mass value="0.14121"/>
            <inertia ixx="0.000068413"  ixy="-0.000000090"  ixz="0.000027110"
            iyy="0.000093037" iyz="0.000000657" izz="0.000068140"/>
        </inertial>
    </link>

    <!-- RIGHT HIP LINK -->

    <joint name="right_hip_joint" type="revolute">
        <parent link="chassis"/>
        <child link="right_hip"/>
        <origin xyz="0 -0.0461 0" rpy="0 0 0"/>
        <axis xyz="0 0 -1"/>
        <limit lower="0" upper="${pi/6}" velocity="100" effort="100"/>
    </joint>

    <link name="right_hip">
        <visual>
            <origin xyz="-0.04505 0.06602 -0.0717" rpy="${pi/2} 0 0"/>
            <geometry>
                <mesh filename="package://droid/description/meshes/right_hip.STL" scale="0.001 0.001 0.001"/>
            </geometry>
            <material name="orange"/>
        </visual>
        <collision>
            <origin xyz="-0.04505 0.06602 -0.0717" rpy="${pi/2} 0 0"/>
            <geometry>
                <mesh filename="package://droid/description/meshes/right_hip.STL" scale="0.001 0.001 0.001"/>
            </geometry>
        </collision>
        <inertial>
            <origin xyz="-0.001594 0.00051 -0.04019" rpy="0 0 0"/>
            <mass value="0.14121"/>
            <inertia ixx="0.000068413"  ixy="0.000000090"  ixz="0.000027110"
            iyy="0.000093037" iyz="-0.000000657" izz="0.000068140"/>
        </inertial>
    </link>
    

</robot>